Workbook

Sheet RAW_INPUT
A1: RAW TRADE SIGNALS IMPORT
A2: Stock | B2: Entry Date | C2: Entry Price | D2: Exit Date | E2: Close Price | F2: Provided Return %
A3: Gujarat Alkalies & C.. | B3: 2013-03-28 | C3: 215 | D3: 2013-06-28 | E3: 178.05 | F3: -17.19
A4: Rain Industries Ltd. | B4: 2013-03-28 | C4: 47.5 | D4: 2013-06-28 | E4: 40 | F4: -15.79
A5: CIE Automotive India.. | B5: 2013-06-28 | C5: 59.45 | D5: 2013-09-30 | E5: 66.8 | F5: 12.36
A6: Suven Life Sciences .. | B6: 2013-09-30 | C6: 42.95 | D6: 2013-12-31 | E6: 72.35 | F6: 68.45
A7: Alembic Ltd. | B7: 2013-09-30 | C7: 13.45 | D7: 2013-12-31 | E7: 14.95 | F7: 11.15
A8: Nucleus Software Exp.. | B8: 2013-09-30 | C8: 95.05 | D8: 2014-03-31 | E8: 217.9 | F8: 129.25
A9: Himatsingka Seide Ltd. | B9: 2013-12-31 | C9: 54.65 | D9: 2014-03-31 | E9: 57.4 | F9: 5.03
A10: Vinati Organics Ltd. | B10: 2013-12-31 | C10: 95.35 | D10: 2014-03-31 | E10: 140.52 | F10: 47.37
A11: Ashiana Housing Ltd. | B11: 2013-12-31 | C11: 70 | D11: 2014-03-31 | E11: 88.8 | F11: 26.86
A12: FIEM Industries Ltd. | B12: 2013-12-31 | C12: 172.15 | D12: 2014-03-31 | E12: 206.25 | F12: 19.81
A13: Hindustan Composites.. | B13: 2013-12-31 | C13: 133.33 | D13: 2014-03-31 | E13: 136.67 | F13: 2.51
A14: Igarashi Motors Indi.. | B14: 2013-12-31 | C14: 74.75 | D14: 2014-03-31 | E14: 152.17 | F14: 103.57
... A791: Prudent Corporate Ad.. | B791: 2024-07-31 | C791: 2295.45 | D791: 2024-07-31 | E791: 2295.45 | F791: 0

Sheet TRADE_CALCULATION
A1: INDEPENDENT TRADE-BY-TRADE AUDIT & FORMULA CALCULATIONS
A2: Trade ID | B2: Stock | C2: Entry Date | D2: Exit Date | E2: Duration | F2: Entry Price | G2: Exit Price | H2: Quantity | I2: Allocated Capital | J2: Calculated P&L | K2: Calculated Return % | L2: Provided Return % | M2: Return Difference % | N2: Winning Trade | O2: Losing Trade | P2: Cumulative P&L | Q2: Cumulative Return % | R2: Equity | S2: Running Peak | T2: Drawdown | U2: Drawdown % | V2: Downside Return Sq
A3: =TEXT(1, """T""0000") | B3: =RAW_INPUT!A3 | C3: =RAW_INPUT!B3 | D3: =RAW_INPUT!D3 | E3: =D3-C3 | F3: =RAW_INPUT!C3 | G3: =RAW_INPUT!E3 | H3: =I3/F3 | I3: =METRICS!$C$14 * 0.02 | J3: =(G3-F3)*H3 | K3: =(G3-F3)/F3*100 | L3: =RAW_INPUT!F3 | M3: =K3-L3 | N3: =IF(J3>0, 1, 0) | O3: =IF(J3<0, 1, 0) | P3: =SUM($J$3:J3) | Q3: =P3/METRICS!$C$14*100 | R3: =METRICS!$C$14+P3 | S3: =MAX($R$3:R3) | T3: =R3-S3 | U3: =(R3-S3)/S3*100 | V3: =IF(K3<0, (K3/100)^2, 0)
A4: =TEXT(2, """T""0000") | B4: =RAW_INPUT!A4 | C4: =RAW_INPUT!B4 | D4: =RAW_INPUT!D4 | E4: =D4-C4 | F4: =RAW_INPUT!C4 | G4: =RAW_INPUT!E4 | H4: =I4/F4 | I4: =METRICS!$C$14 * 0.02 | J4: =(G4-F4)*H4 | K4: =(G4-F4)/F4*100 | L4: =RAW_INPUT!F4 | M4: =K4-L4 | N4: =IF(J4>0, 1, 0) | O4: =IF(J4<0, 1, 0) | P4: =SUM($J$3:J4) | Q4: =P4/METRICS!$C$14*100 | R4: =METRICS!$C$14+P4 | S4: =MAX($R$3:R4) | T4: =R4-S4 | U4: =(R4-S4)/S4*100 | V4: =IF(K4<0, (K4/100)^2, 0)
A5: =TEXT(3, """T""0000") | B5: =RAW_INPUT!A5 | C5: =RAW_INPUT!B5 | D5: =RAW_INPUT!D5 | E5: =D5-C5 | F5: =RAW_INPUT!C5 | G5: =RAW_INPUT!E5 | H5: =I5/F5 | I5: =METRICS!$C$14 * 0.02 | J5: =(G5-F5)*H5 | K5: =(G5-F5)/F5*100 | L5: =RAW_INPUT!F5 | M5: =K5-L5 | N5: =IF(J5>0, 1, 0) | O5: =IF(J5<0, 1, 0) | P5: =SUM($J$3:J5) | Q5: =P5/METRICS!$C$14*100 | R5: =METRICS!$C$14+P5 | S5: =MAX($R$3:R5) | T5: =R5-S5 | U5: =(R5-S5)/S5*100 | V5: =IF(K5<0, (K5/100)^2, 0)
A6: =TEXT(4, """T""0000") | B6: =RAW_INPUT!A6 | C6: =RAW_INPUT!B6 | D6: =RAW_INPUT!D6 | E6: =D6-C6 | F6: =RAW_INPUT!C6 | G6: =RAW_INPUT!E6 | H6: =I6/F6 | I6: =METRICS!$C$14 * 0.02 | J6: =(G6-F6)*H6 | K6: =(G6-F6)/F6*100 | L6: =RAW_INPUT!F6 | M6: =K6-L6 | N6: =IF(J6>0, 1, 0) | O6: =IF(J6<0, 1, 0) | P6: =SUM($J$3:J6) | Q6: =P6/METRICS!$C$14*100 | R6: =METRICS!$C$14+P6 | S6: =MAX($R$3:R6) | T6: =R6-S6 | U6: =(R6-S6)/S6*100 | V6: =IF(K6<0, (K6/100)^2, 0)
A7: =TEXT(5, """T""0000") | B7: =RAW_INPUT!A7 | C7: =RAW_INPUT!B7 | D7: =RAW_INPUT!D7 | E7: =D7-C7 | F7: =RAW_INPUT!C7 | G7: =RAW_INPUT!E7 | H7: =I7/F7 | I7: =METRICS!$C$14 * 0.02 | J7: =(G7-F7)*H7 | K7: =(G7-F7)/F7*100 | L7: =RAW_INPUT!F7 | M7: =K7-L7 | N7: =IF(J7>0, 1, 0) | O7: =IF(J7<0, 1, 0) | P7: =SUM($J$3:J7) | Q7: =P7/METRICS!$C$14*100 | R7: =METRICS!$C$14+P7 | S7: =MAX($R$3:R7) | T7: =R7-S7 | U7: =(R7-S7)/S7*100 | V7: =IF(K7<0, (K7/100)^2, 0)
A8: =TEXT(6, """T""0000") | B8: =RAW_INPUT!A8 | C8: =RAW_INPUT!B8 | D8: =RAW_INPUT!D8 | E8: =D8-C8 | F8: =RAW_INPUT!C8 | G8: =RAW_INPUT!E8 | H8: =I8/F8 | I8: =METRICS!$C$14 * 0.02 | J8: =(G8-F8)*H8 | K8: =(G8-F8)/F8*100 | L8: =RAW_INPUT!F8 | M8: =K8-L8 | N8: =IF(J8>0, 1, 0) | O8: =IF(J8<0, 1, 0) | P8: =SUM($J$3:J8) | Q8: =P8/METRICS!$C$14*100 | R8: =METRICS!$C$14+P8 | S8: =MAX($R$3:R8) | T8: =R8-S8 | U8: =(R8-S8)/S8*100 | V8: =IF(K8<0, (K8/100)^2, 0)
A9: =TEXT(7, """T""0000") | B9: =RAW_INPUT!A9 | C9: =RAW_INPUT!B9 | D9: =RAW_INPUT!D9 | E9: =D9-C9 | F9: =RAW_INPUT!C9 | G9: =RAW_INPUT!E9 | H9: =I9/F9 | I9: =METRICS!$C$14 * 0.02 | J9: =(G9-F9)*H9 | K9: =(G9-F9)/F9*100 | L9: =RAW_INPUT!F9 | M9: =K9-L9 | N9: =IF(J9>0, 1, 0) | O9: =IF(J9<0, 1, 0) | P9: =SUM($J$3:J9) | Q9: =P9/METRICS!$C$14*100 | R9: =METRICS!$C$14+P9 | S9: =MAX($R$3:R9) | T9: =R9-S9 | U9: =(R9-S9)/S9*100 | V9: =IF(K9<0, (K9/100)^2, 0)
A10: =TEXT(8, """T""0000") | B10: =RAW_INPUT!A10 | C10: =RAW_INPUT!B10 | D10: =RAW_INPUT!D10 | E10: =D10-C10 | F10: =RAW_INPUT!C10 | G10: =RAW_INPUT!E10 | H10: =I10/F10 | I10: =METRICS!$C$14 * 0.02 | J10: =(G10-F10)*H10 | K10: =(G10-F10)/F10*100 | L10: =RAW_INPUT!F10 | M10: =K10-L10 | N10: =IF(J10>0, 1, 0) | O10: =IF(J10<0, 1, 0) | P10: =SUM($J$3:J10) | Q10: =P10/METRICS!$C$14*100 | R10: =METRICS!$C$14+P10 | S10: =MAX($R$3:R10) | T10: =R10-S10 | U10: =(R10-S10)/S10*100 | V10: =IF(K10<0, (K10/100)^2, 0)
A11: =TEXT(9, """T""0000") | B11: =RAW_INPUT!A11 | C11: =RAW_INPUT!B11 | D11: =RAW_INPUT!D11 | E11: =D11-C11 | F11: =RAW_INPUT!C11 | G11: =RAW_INPUT!E11 | H11: =I11/F11 | I11: =METRICS!$C$14 * 0.02 | J11: =(G11-F11)*H11 | K11: =(G11-F11)/F11*100 | L11: =RAW_INPUT!F11 | M11: =K11-L11 | N11: =IF(J11>0, 1, 0) | O11: =IF(J11<0, 1, 0) | P11: =SUM($J$3:J11) | Q11: =P11/METRICS!$C$14*100 | R11: =METRICS!$C$14+P11 | S11: =MAX($R$3:R11) | T11: =R11-S11 | U11: =(R11-S11)/S11*100 | V11: =IF(K11<0, (K11/100)^2, 0)
A12: =TEXT(10, """T""0000") | B12: =RAW_INPUT!A12 | C12: =RAW_INPUT!B12 | D12: =RAW_INPUT!D12 | E12: =D12-C12 | F12: =RAW_INPUT!C12 | G12: =RAW_INPUT!E12 | H12: =I12/F12 | I12: =METRICS!$C$14 * 0.02 | J12: =(G12-F12)*H12 | K12: =(G12-F12)/F12*100 | L12: =RAW_INPUT!F12 | M12: =K12-L12 | N12: =IF(J12>0, 1, 0) | O12: =IF(J12<0, 1, 0) | P12: =SUM($J$3:J12) | Q12: =P12/METRICS!$C$14*100 | R12: =METRICS!$C$14+P12 | S12: =MAX($R$3:R12) | T12: =R12-S12 | U12: =(R12-S12)/S12*100 | V12: =IF(K12<0, (K12/100)^2, 0)
A13: =TEXT(11, """T""0000") | B13: =RAW_INPUT!A13 | C13: =RAW_INPUT!B13 | D13: =RAW_INPUT!D13 | E13: =D13-C13 | F13: =RAW_INPUT!C13 | G13: =RAW_INPUT!E13 | H13: =I13/F13 | I13: =METRICS!$C$14 * 0.02 | J13: =(G13-F13)*H13 | K13: =(G13-F13)/F13*100 | L13: =RAW_INPUT!F13 | M13: =K13-L13 | N13: =IF(J13>0, 1, 0) | O13: =IF(J13<0, 1, 0) | P13: =SUM($J$3:J13) | Q13: =P13/METRICS!$C$14*100 | R13: =METRICS!$C$14+P13 | S13: =MAX($R$3:R13) | T13: =R13-S13 | U13: =(R13-S13)/S13*100 | V13: =IF(K13<0, (K13/100)^2, 0)
A14: =TEXT(12, """T""0000") | B14: =RAW_INPUT!A14 | C14: =RAW_INPUT!B14 | D14: =RAW_INPUT!D14 | E14: =D14-C14 | F14: =RAW_INPUT!C14 | G14: =RAW_INPUT!E14 | H14: =I14/F14 | I14: =METRICS!$C$14 * 0.02 | J14: =(G14-F14)*H14 | K14: =(G14-F14)/F14*100 | L14: =RAW_INPUT!F14 | M14: =K14-L14 | N14: =IF(J14>0, 1, 0) | O14: =IF(J14<0, 1, 0) | P14: =SUM($J$3:J14) | Q14: =P14/METRICS!$C$14*100 | R14: =METRICS!$C$14+P14 | S14: =MAX($R$3:R14) | T14: =R14-S14 | U14: =(R14-S14)/S14*100 | V14: =IF(K14<0, (K14/100)^2, 0)
A15: =TEXT(13, """T""0000") | B15: =RAW_INPUT!A15 | C15: =RAW_INPUT!B15 | D15: =RAW_INPUT!D15 | E15: =D15-C15 | F15: =RAW_INPUT!C15 | G15: =RAW_INPUT!E15 | H15: =I15/F15 | I15: =METRICS!$C$14 * 0.02 | J15: =(G15-F15)*H15 | K15: =(G15-F15)/F15*100 | L15: =RAW_INPUT!F15 | M15: =K15-L15 | N15: =IF(J15>0, 1, 0) | O15: =IF(J15<0, 1, 0) | P15: =SUM($J$3:J15) | Q15: =P15/METRICS!$C$14*100 | R15: =METRICS!$C$14+P15 | S15: =MAX($R$3:R15) | T15: =R15-S15 | U15: =(R15-S15)/S15*100 | V15: =IF(K15<0, (K15/100)^2, 0)
A16: =TEXT(14, """T""0000") | B16: =RAW_INPUT!A16 | C16: =RAW_INPUT!B16 | D16: =RAW_INPUT!D16 | E16: =D16-C16 | F16: =RAW_INPUT!C16 | G16: =RAW_INPUT!E16 | H16: =I16/F16 | I16: =METRICS!$C$14 * 0.02 | J16: =(G16-F16)*H16 | K16: =(G16-F16)/F16*100 | L16: =RAW_INPUT!F16 | M16: =K16-L16 | N16: =IF(J16>0, 1, 0) | O16: =IF(J16<0, 1, 0) | P16: =SUM($J$3:J16) | Q16: =P16/METRICS!$C$14*100 | R16: =METRICS!$C$14+P16 | S16: =MAX($R$3:R16) | T16: =R16-S16 | U16: =(R16-S16)/S16*100 | V16: =IF(K16<0, (K16/100)^2, 0)
A17: =TEXT(15, """T""0000") | B17: =RAW_INPUT!A17 | C17: =RAW_INPUT!B17 | D17: =RAW_INPUT!D17 | E17: =D17-C17 | F17: =RAW_INPUT!C17 | G17: =RAW_INPUT!E17 | H17: =I17/F17 | I17: =METRICS!$C$14 * 0.02 | J17: =(G17-F17)*H17 | K17: =(G17-F17)/F17*100 | L17: =RAW_INPUT!F17 | M17: =K17-L17 | N17: =IF(J17>0, 1, 0) | O17: =IF(J17<0, 1, 0) | P17: =SUM($J$3:J17) | Q17: =P17/METRICS!$C$14*100 | R17: =METRICS!$C$14+P17 | S17: =MAX($R$3:R17) | T17: =R17-S17 | U17: =(R17-S17)/S17*100 | V17: =IF(K17<0, (K17/100)^2, 0)
A18: =TEXT(16, """T""0000") | B18: =RAW_INPUT!A18 | C18: =RAW_INPUT!B18 | D18: =RAW_INPUT!D18 | E18: =D18-C18 | F18: =RAW_INPUT!C18 | G18: =RAW_INPUT!E18 | H18: =I18/F18 | I18: =METRICS!$C$14 * 0.02 | J18: =(G18-F18)*H18 | K18: =(G18-F18)/F18*100 | L18: =RAW_INPUT!F18 | M18: =K18-L18 | N18: =IF(J18>0, 1, 0) | O18: =IF(J18<0, 1, 0) | P18: =SUM($J$3:J18) | Q18: =P18/METRICS!$C$14*100 | R18: =METRICS!$C$14+P18 | S18: =MAX($R$3:R18) | T18: =R18-S18 | U18: =(R18-S18)/S18*100 | V18: =IF(K18<0, (K18/100)^2, 0)
A19: =TEXT(17, """T""0000") | B19: =RAW_INPUT!A19 | C19: =RAW_INPUT!B19 | D19: =RAW_INPUT!D19 | E19: =D19-C19 | F19: =RAW_INPUT!C19 | G19: =RAW_INPUT!E19 | H19: =I19/F19 | I19: =METRICS!$C$14 * 0.02 | J19: =(G19-F19)*H19 | K19: =(G19-F19)/F19*100 | L19: =RAW_INPUT!F19 | M19: =K19-L19 | N19: =IF(J19>0, 1, 0) | O19: =IF(J19<0, 1, 0) | P19: =SUM($J$3:J19) | Q19: =P19/METRICS!$C$14*100 | R19: =METRICS!$C$14+P19 | S19: =MAX($R$3:R19) | T19: =R19-S19 | U19: =(R19-S19)/S19*100 | V19: =IF(K19<0, (K19/100)^2, 0)
A20: =TEXT(18, """T""0000") | B20: =RAW_INPUT!A20 | C20: =RAW_INPUT!B20 | D20: =RAW_INPUT!D20 | E20: =D20-C20 | F20: =RAW_INPUT!C20 | G20: =RAW_INPUT!E20 | H20: =I20/F20 | I20: =METRICS!$C$14 * 0.02 | J20: =(G20-F20)*H20 | K20: =(G20-F20)/F20*100 | L20: =RAW_INPUT!F20 | M20: =K20-L20 | N20: =IF(J20>0, 1, 0) | O20: =IF(J20<0, 1, 0) | P20: =SUM($J$3:J20) | Q20: =P20/METRICS!$C$14*100 | R20: =METRICS!$C$14+P20 | S20: =MAX($R$3:R20) | T20: =R20-S20 | U20: =(R20-S20)/S20*100 | V20: =IF(K20<0, (K20/100)^2, 0)
A21: =TEXT(19, """T""0000") | B21: =RAW_INPUT!A21 | C21: =RAW_INPUT!B21 | D21: =RAW_INPUT!D21 | E21: =D21-C21 | F21: =RAW_INPUT!C21 | G21: =RAW_INPUT!E21 | H21: =I21/F21 | I21: =METRICS!$C$14 * 0.02 | J21: =(G21-F21)*H21 | K21: =(G21-F21)/F21*100 | L21: =RAW_INPUT!F21 | M21: =K21-L21 | N21: =IF(J21>0, 1, 0) | O21: =IF(J21<0, 1, 0) | P21: =SUM($J$3:J21) | Q21: =P21/METRICS!$C$14*100 | R21: =METRICS!$C$14+P21 | S21: =MAX($R$3:R21) | T21: =R21-S21 | U21: =(R21-S21)/S21*100 | V21: =IF(K21<0, (K21/100)^2, 0)
A22: =TEXT(20, """T""0000") | B22: =RAW_INPUT!A22 | C22: =RAW_INPUT!B22 | D22: =RAW_INPUT!D22 | E22: =D22-C22 | F22: =RAW_INPUT!C22 | G22: =RAW_INPUT!E22 | H22: =I22/F22 | I22: =METRICS!$C$14 * 0.02 | J22: =(G22-F22)*H22 | K22: =(G22-F22)/F22*100 | L22: =RAW_INPUT!F22 | M22: =K22-L22 | N22: =IF(J22>0, 1, 0) | O22: =IF(J22<0, 1, 0) | P22: =SUM($J$3:J22) | Q22: =P22/METRICS!$C$14*100 | R22: =METRICS!$C$14+P22 | S22: =MAX($R$3:R22) | T22: =R22-S22 | U22: =(R22-S22)/S22*100 | V22: =IF(K22<0, (K22/100)^2, 0)
A23: =TEXT(21, """T""0000") | B23: =RAW_INPUT!A23 | C23: =RAW_INPUT!B23 | D23: =RAW_INPUT!D23 | E23: =D23-C23 | F23: =RAW_INPUT!C23 | G23: =RAW_INPUT!E23 | H23: =I23/F23 | I23: =METRICS!$C$14 * 0.02 | J23: =(G23-F23)*H23 | K23: =(G23-F23)/F23*100 | L23: =RAW_INPUT!F23 | M23: =K23-L23 | N23: =IF(J23>0, 1, 0) | O23: =IF(J23<0, 1, 0) | P23: =SUM($J$3:J23) | Q23: =P23/METRICS!$C$14*100 | R23: =METRICS!$C$14+P23 | S23: =MAX($R$3:R23) | T23: =R23-S23 | U23: =(R23-S23)/S23*100 | V23: =IF(K23<0, (K23/100)^2, 0)
A24: =TEXT(22, """T""0000") | B24: =RAW_INPUT!A24 | C24: =RAW_INPUT!B24 | D24: =RAW_INPUT!D24 | E24: =D24-C24 | F24: =RAW_INPUT!C24 | G24: =RAW_INPUT!E24 | H24: =I24/F24 | I24: =METRICS!$C$14 * 0.02 | J24: =(G24-F24)*H24 | K24: =(G24-F24)/F24*100 | L24: =RAW_INPUT!F24 | M24: =K24-L24 | N24: =IF(J24>0, 1, 0) | O24: =IF(J24<0, 1, 0) | P24: =SUM($J$3:J24) | Q24: =P24/METRICS!$C$14*100 | R24: =METRICS!$C$14+P24 | S24: =MAX($R$3:R24) | T24: =R24-S24 | U24: =(R24-S24)/S24*100 | V24: =IF(K24<0, (K24/100)^2, 0)
A25: =TEXT(23, """T""0000") | B25: =RAW_INPUT!A25 | C25: =RAW_INPUT!B25 | D25: =RAW_INPUT!D25 | E25: =D25-C25 | F25: =RAW_INPUT!C25 | G25: =RAW_INPUT!E25 | H25: =I25/F25 | I25: =METRICS!$C$14 * 0.02 | J25: =(G25-F25)*H25 | K25: =(G25-F25)/F25*100 | L25: =RAW_INPUT!F25 | M25: =K25-L25 | N25: =IF(J25>0, 1, 0) | O25: =IF(J25<0, 1, 0) | P25: =SUM($J$3:J25) | Q25: =P25/METRICS!$C$14*100 | R25: =METRICS!$C$14+P25 | S25: =MAX($R$3:R25) | T25: =R25-S25 | U25: =(R25-S25)/S25*100 | V25: =IF(K25<0, (K25/100)^2, 0)
A26: =TEXT(24, """T""0000") | B26: =RAW_INPUT!A26 | C26: =RAW_INPUT!B26 | D26: =RAW_INPUT!D26 | E26: =D26-C26 | F26: =RAW_INPUT!C26 | G26: =RAW_INPUT!E26 | H26: =I26/F26 | I26: =METRICS!$C$14 * 0.02 | J26: =(G26-F26)*H26 | K26: =(G26-F26)/F26*100 | L26: =RAW_INPUT!F26 | M26: =K26-L26 | N26: =IF(J26>0, 1, 0) | O26: =IF(J26<0, 1, 0) | P26: =SUM($J$3:J26) | Q26: =P26/METRICS!$C$14*100 | R26: =METRICS!$C$14+P26 | S26: =MAX($R$3:R26) | T26: =R26-S26 | U26: =(R26-S26)/S26*100 | V26: =IF(K26<0, (K26/100)^2, 0)
A27: =TEXT(25, """T""0000") | B27: =RAW_INPUT!A27 | C27: =RAW_INPUT!B27 | D27: =RAW_INPUT!D27 | E27: =D27-C27 | F27: =RAW_INPUT!C27 | G27: =RAW_INPUT!E27 | H27: =I27/F27 | I27: =METRICS!$C$14 * 0.02 | J27: =(G27-F27)*H27 | K27: =(G27-F27)/F27*100 | L27: =RAW_INPUT!F27 | M27: =K27-L27 | N27: =IF(J27>0, 1, 0) | O27: =IF(J27<0, 1, 0) | P27: =SUM($J$3:J27) | Q27: =P27/METRICS!$C$14*100 | R27: =METRICS!$C$14+P27 | S27: =MAX($R$3:R27) | T27: =R27-S27 | U27: =(R27-S27)/S27*100 | V27: =IF(K27<0, (K27/100)^2, 0)
A28: =TEXT(26, """T""0000") | B28: =RAW_INPUT!A28 | C28: =RAW_INPUT!B28 | D28: =RAW_INPUT!D28 | E28: =D28-C28 | F28: =RAW_INPUT!C28 | G28: =RAW_INPUT!E28 | H28: =I28/F28 | I28: =METRICS!$C$14 * 0.02 | J28: =(G28-F28)*H28 | K28: =(G28-F28)/F28*100 | L28: =RAW_INPUT!F28 | M28: =K28-L28 | N28: =IF(J28>0, 1, 0) | O28: =IF(J28<0, 1, 0) | P28: =SUM($J$3:J28) | Q28: =P28/METRICS!$C$14*100 | R28: =METRICS!$C$14+P28 | S28: =MAX($R$3:R28) | T28: =R28-S28 | U28: =(R28-S28)/S28*100 | V28: =IF(K28<0, (K28/100)^2, 0)
A29: =TEXT(27, """T""0000") | B29: =RAW_INPUT!A29 | C29: =RAW_INPUT!B29 | D29: =RAW_INPUT!D29 | E29: =D29-C29 | F29: =RAW_INPUT!C29 | G29: =RAW_INPUT!E29 | H29: =I29/F29 | I29: =METRICS!$C$14 * 0.02 | J29: =(G29-F29)*H29 | K29: =(G29-F29)/F29*100 | L29: =RAW_INPUT!F29 | M29: =K29-L29 | N29: =IF(J29>0, 1, 0) | O29: =IF(J29<0, 1, 0) | P29: =SUM($J$3:J29) | Q29: =P29/METRICS!$C$14*100 | R29: =METRICS!$C$14+P29 | S29: =MAX($R$3:R29) | T29: =R29-S29 | U29: =(R29-S29)/S29*100 | V29: =IF(K29<0, (K29/100)^2, 0)
A30: =TEXT(28, """T""0000") | B30: =RAW_INPUT!A30 | C30: =RAW_INPUT!B30 | D30: =RAW_INPUT!D30 | E30: =D30-C30 | F30: =RAW_INPUT!C30 | G30: =RAW_INPUT!E30 | H30: =I30/F30 | I30: =METRICS!$C$14 * 0.02 | J30: =(G30-F30)*H30 | K30: =(G30-F30)/F30*100 | L30: =RAW_INPUT!F30 | M30: =K30-L30 | N30: =IF(J30>0, 1, 0) | O30: =IF(J30<0, 1, 0) | P30: =SUM($J$3:J30) | Q30: =P30/METRICS!$C$14*100 | R30: =METRICS!$C$14+P30 | S30: =MAX($R$3:R30) | T30: =R30-S30 | U30: =(R30-S30)/S30*100 | V30: =IF(K30<0, (K30/100)^2, 0)
A31: =TEXT(29, """T""0000") | B31: =RAW_INPUT!A31 | C31: =RAW_INPUT!B31 | D31: =RAW_INPUT!D31 | E31: =D31-C31 | F31: =RAW_INPUT!C31 | G31: =RAW_INPUT!E31 | H31: =I31/F31 | I31: =METRICS!$C$14 * 0.02 | J31: =(G31-F31)*H31 | K31: =(G31-F31)/F31*100 | L31: =RAW_INPUT!F31 | M31: =K31-L31 | N31: =IF(J31>0, 1, 0) | O31: =IF(J31<0, 1, 0) | P31: =SUM($J$3:J31) | Q31: =P31/METRICS!$C$14*100 | R31: =METRICS!$C$14+P31 | S31: =MAX($R$3:R31) | T31: =R31-S31 | U31: =(R31-S31)/S31*100 | V31: =IF(K31<0, (K31/100)^2, 0)
A32: =TEXT(30, """T""0000") | B32: =RAW_INPUT!A32 | C32: =RAW_INPUT!B32 | D32: =RAW_INPUT!D32 | E32: =D32-C32 | F32: =RAW_INPUT!C32 | G32: =RAW_INPUT!E32 | H32: =I32/F32 | I32: =METRICS!$C$14 * 0.02 | J32: =(G32-F32)*H32 | K32: =(G32-F32)/F32*100 | L32: =RAW_INPUT!F32 | M32: =K32-L32 | N32: =IF(J32>0, 1, 0) | O32: =IF(J32<0, 1, 0) | P32: =SUM($J$3:J32) | Q32: =P32/METRICS!$C$14*100 | R32: =METRICS!$C$14+P32 | S32: =MAX($R$3:R32) | T32: =R32-S32 | U32: =(R32-S32)/S32*100 | V32: =IF(K32<0, (K32/100)^2, 0)
A33: =TEXT(31, """T""0000") | B33: =RAW_INPUT!A33 | C33: =RAW_INPUT!B33 | D33: =RAW_INPUT!D33 | E33: =D33-C33 | F33: =RAW_INPUT!C33 | G33: =RAW_INPUT!E33 | H33: =I33/F33 | I33: =METRICS!$C$14 * 0.02 | J33: =(G33-F33)*H33 | K33: =(G33-F33)/F33*100 | L33: =RAW_INPUT!F33 | M33: =K33-L33 | N33: =IF(J33>0, 1, 0) | O33: =IF(J33<0, 1, 0) | P33: =SUM($J$3:J33) | Q33: =P33/METRICS!$C$14*100 | R33: =METRICS!$C$14+P33 | S33: =MAX($R$3:R33) | T33: =R33-S33 | U33: =(R33-S33)/S33*100 | V33: =IF(K33<0, (K33/100)^2, 0)
A34: =TEXT(32, """T""0000") | B34: =RAW_INPUT!A34 | C34: =RAW_INPUT!B34 | D34: =RAW_INPUT!D34 | E34: =D34-C34 | F34: =RAW_INPUT!C34 | G34: =RAW_INPUT!E34 | H34: =I34/F34 | I34: =METRICS!$C$14 * 0.02 | J34: =(G34-F34)*H34 | K34: =(G34-F34)/F34*100 | L34: =RAW_INPUT!F34 | M34: =K34-L34 | N34: =IF(J34>0, 1, 0) | O34: =IF(J34<0, 1, 0) | P34: =SUM($J$3:J34) | Q34: =P34/METRICS!$C$14*100 | R34: =METRICS!$C$14+P34 | S34: =MAX($R$3:R34) | T34: =R34-S34 | U34: =(R34-S34)/S34*100 | V34: =IF(K34<0, (K34/100)^2, 0)
A35: =TEXT(33, """T""0000") | B35: =RAW_INPUT!A35 | C35: =RAW_INPUT!B35 | D35: =RAW_INPUT!D35 | E35: =D35-C35 | F35: =RAW_INPUT!C35 | G35: =RAW_INPUT!E35 | H35: =I35/F35 | I35: =METRICS!$C$14 * 0.02 | J35: =(G35-F35)*H35 | K35: =(G35-F35)/F35*100 | L35: =RAW_INPUT!F35 | M35: =K35-L35 | N35: =IF(J35>0, 1, 0) | O35: =IF(J35<0, 1, 0) | P35: =SUM($J$3:J35) | Q35: =P35/METRICS!$C$14*100 | R35: =METRICS!$C$14+P35 | S35: =MAX($R$3:R35) | T35: =R35-S35 | U35: =(R35-S35)/S35*100 | V35: =IF(K35<0, (K35/100)^2, 0)
A36: =TEXT(34, """T""0000") | B36: =RAW_INPUT!A36 | C36: =RAW_INPUT!B36 | D36: =RAW_INPUT!D36 | E36: =D36-C36 | F36: =RAW_INPUT!C36 | G36: =RAW_INPUT!E36 | H36: =I36/F36 | I36: =METRICS!$C$14 * 0.02 | J36: =(G36-F36)*H36 | K36: =(G36-F36)/F36*100 | L36: =RAW_INPUT!F36 | M36: =K36-L36 | N36: =IF(J36>0, 1, 0) | O36: =IF(J36<0, 1, 0) | P36: =SUM($J$3:J36) | Q36: =P36/METRICS!$C$14*100 | R36: =METRICS!$C$14+P36 | S36: =MAX($R$3:R36) | T36: =R36-S36 | U36: =(R36-S36)/S36*100 | V36: =IF(K36<0, (K36/100)^2, 0)
A37: =TEXT(35, """T""0000") | B37: =RAW_INPUT!A37 | C37: =RAW_INPUT!B37 | D37: =RAW_INPUT!D37 | E37: =D37-C37 | F37: =RAW_INPUT!C37 | G37: =RAW_INPUT!E37 | H37: =I37/F37 | I37: =METRICS!$C$14 * 0.02 | J37: =(G37-F37)*H37 | K37: =(G37-F37)/F37*100 | L37: =RAW_INPUT!F37 | M37: =K37-L37 | N37: =IF(J37>0, 1, 0) | O37: =IF(J37<0, 1, 0) | P37: =SUM($J$3:J37) | Q37: =P37/METRICS!$C$14*100 | R37: =METRICS!$C$14+P37 | S37: =MAX($R$3:R37) | T37: =R37-S37 | U37: =(R37-S37)/S37*100 | V37: =IF(K37<0, (K37/100)^2, 0)
A38: =TEXT(36, """T""0000") | B38: =RAW_INPUT!A38 | C38: =RAW_INPUT!B38 | D38: =RAW_INPUT!D38 | E38: =D38-C38 | F38: =RAW_INPUT!C38 | G38: =RAW_INPUT!E38 | H38: =I38/F38 | I38: =METRICS!$C$14 * 0.02 | J38: =(G38-F38)*H38 | K38: =(G38-F38)/F38*100 | L38: =RAW_INPUT!F38 | M38: =K38-L38 | N38: =IF(J38>0, 1, 0) | O38: =IF(J38<0, 1, 0) | P38: =SUM($J$3:J38) | Q38: =P38/METRICS!$C$14*100 | R38: =METRICS!$C$14+P38 | S38: =MAX($R$3:R38) | T38: =R38-S38 | U38: =(R38-S38)/S38*100 | V38: =IF(K38<0, (K38/100)^2, 0)
A39: =TEXT(37, """T""0000") | B39: =RAW_INPUT!A39 | C39: =RAW_INPUT!B39 | D39: =RAW_INPUT!D39 | E39: =D39-C39 | F39: =RAW_INPUT!C39 | G39: =RAW_INPUT!E39 | H39: =I39/F39 | I39: =METRICS!$C$14 * 0.02 | J39: =(G39-F39)*H39 | K39: =(G39-F39)/F39*100 | L39: =RAW_INPUT!F39 | M39: =K39-L39 | N39: =IF(J39>0, 1, 0) | O39: =IF(J39<0, 1, 0) | P39: =SUM($J$3:J39) | Q39: =P39/METRICS!$C$14*100 | R39: =METRICS!$C$14+P39 | S39: =MAX($R$3:R39) | T39: =R39-S39 | U39: =(R39-S39)/S39*100 | V39: =IF(K39<0, (K39/100)^2, 0)
A40: =TEXT(38, """T""0000") | B40: =RAW_INPUT!A40 | C40: =RAW_INPUT!B40 | D40: =RAW_INPUT!D40 | E40: =D40-C40 | F40: =RAW_INPUT!C40 | G40: =RAW_INPUT!E40 | H40: =I40/F40 | I40: =METRICS!$C$14 * 0.02 | J40: =(G40-F40)*H40 | K40: =(G40-F40)/F40*100 | L40: =RAW_INPUT!F40 | M40: =K40-L40 | N40: =IF(J40>0, 1, 0) | O40: =IF(J40<0, 1, 0) | P40: =SUM($J$3:J40) | Q40: =P40/METRICS!$C$14*100 | R40: =METRICS!$C$14+P40 | S40: =MAX($R$3:R40) | T40: =R40-S40 | U40: =(R40-S40)/S40*100 | V40: =IF(K40<0, (K40/100)^2, 0)
...

Sheet METRICS
A1: QUANTLAB METRICS VERIFICATION & RECONCILIATION
A2: Metric Name | B2: Python Value | C2: Excel Formula | D2: Formula Used | E2: Difference | F2: Status
A3: Total Trades | B3: 789 | C3: =COUNT(TRADE_CALCULATION!J$3:J$791) | D3: COUNT(TRADE_CALCULATION!J3:J791) | E3: =ABS(B3-C3) | F3: =IF(E3<=0.0001, "PASS", "FAIL")
A4: Winning Trades | B4: 403 | C4: =SUM(TRADE_CALCULATION!N$3:N$791) | D4: SUM(TRADE_CALCULATION!N3:N791) | E4: =ABS(B4-C4) | F4: =IF(E4<=0.0001, "PASS", "FAIL")
A5: Losing Trades | B5: 309 | C5: =SUM(TRADE_CALCULATION!O$3:O$791) | D5: SUM(TRADE_CALCULATION!O3:O791) | E5: =ABS(B5-C5) | F5: =IF(E5<=0.0001, "PASS", "FAIL")
A6: Win Rate | B6: 0.510773 | C6: =C4/C3 | D6: =WinningTrades/TotalTrades (C4/C3) | E6: =ABS(B6-C6) | F6: =IF(E6<=0.0001, "PASS", "FAIL")
A7: Loss Rate | B7: 0.391635 | C7: =C5/C3 | D7: =LosingTrades/TotalTrades (C5/C3) | E7: =ABS(B7-C7) | F7: =IF(E7<=0.0001, "PASS", "FAIL")
A8: Gross Profit | B8: 19981766 | C8: =SUMIF(TRADE_CALCULATION!J$3:J$791, ">0") | D8: SUMIF(TRADE_CALCULATION!J3:J791, ">0") | E8: =ABS(B8-C8) | F8: =IF(E8<=0.0001, "PASS", "FAIL")
A9: Gross Loss | B9: -8585798.7 | C9: =SUMIF(TRADE_CALCULATION!J$3:J$791, "<0") | D9: SUMIF(TRADE_CALCULATION!J3:J791, "<0") | E9: =ABS(B9-C9) | F9: =IF(E9<=0.0001, "PASS", "FAIL")
A10: Profit Factor | B10: 2.327304 | C10: =C8/ABS(C9) | D10: =GrossProfit/ABS(GrossLoss) (C8/ABS(C9)) | E10: =ABS(B10-C10) | F10: =IF(E10<=0.0001, "PASS", "FAIL")
A11: Average Win | B11: 49582.55 | C11: =C8/C4 | D11: =GrossProfit/WinningTrades (C8/C4) | E11: =ABS(B11-C11) | F11: =IF(E11<=0.0001, "PASS", "FAIL")
A12: Average Loss | B12: -27785.76 | C12: =C9/C5 | D12: =GrossLoss/LosingTrades (C9/C5) | E12: =ABS(B12-C12) | F12: =IF(E12<=0.0001, "PASS", "FAIL")
A13: Expectancy | B13: 14443.56 | C13: =(C6*C11)+(C7*C12) | D13: =(WinRate*AvgWin)+(LossRate*AvgLoss) ((C6*C11)+(C7*C12)) | E13: =ABS(B13-C13) | F13: =IF(E13<=0.0001, "PASS", "FAIL")
A14: Initial Capital | B14: 10000000 | C14: =10000000.0 | D14: 10000000.0 | E14: =ABS(B14-C14) | F14: =IF(E14<=0.0001, "PASS", "FAIL")
A15: Total P&L | B15: 11395967 | C15: =SUM(TRADE_CALCULATION!J$3:J$791) | D15: SUM(TRADE_CALCULATION!J3:J791) | E15: =ABS(B15-C15) | F15: =IF(E15<=0.0001, "PASS", "FAIL")
A16: Final Equity | B16: 21395967 | C16: =C14+C15 | D16: =InitialCapital+TotalPnL (C14+C15) | E16: =ABS(B16-C16) | F16: =IF(E16<=0.0001, "PASS", "FAIL")
A17: Total Return | B17: 1.139597 | C17: =(C16-C14)/C14 | D17: =(FinalEquity-InitialCapital)/InitialCapital | E17: =ABS(B17-C17) | F17: =IF(E17<=0.0001, "PASS", "FAIL")
A18: Trading Years | B18: 11.342916 | C18: =(MAX(TRADE_CALCULATION!D$3:D$791)-MIN(TRADE_CALCULATION!C$3:C$791))/365.25 | D18: (MAX(ExitDate)-MIN(EntryDate))/365.25 | E18: =ABS(B18-C18) | F18: =IF(E18<=0.0001, "PASS", "FAIL")
A19: CAGR | B19: 0.069356 | C19: =(C16/C14)^(1/C18)-1 | D19: =(FinalEquity/InitialCapital)^(1/Years)-1 | E19: =ABS(B19-C19) | F19: =IF(E19<=0.0001, "PASS", "FAIL")
A20: Mean P&L | B20: 14443.56 | C20: =AVERAGE(TRADE_CALCULATION!J$3:J$791) | D20: AVERAGE(TRADE_CALCULATION!J3:J791) | E20: =ABS(B20-C20) | F20: =IF(E20<=0.0001, "PASS", "FAIL")
A21: Median P&L | B21: 713.52 | C21: =MEDIAN(TRADE_CALCULATION!J$3:J$791) | D21: MEDIAN(TRADE_CALCULATION!J3:J791) | E21: =ABS(B21-C21) | F21: =IF(E21<=0.0001, "PASS", "FAIL")
A22: Std Dev of P&L | B22: 55639.74 | C22: =STDEV.S(TRADE_CALCULATION!J$3:J$791) | D22: STDEV.S(TRADE_CALCULATION!J3:J791) | E22: =ABS(B22-C22) | F22: =IF(E22<=0.0001, "PASS", "FAIL")
A23: Skewness | B23: 1.782539 | C23: =SKEW(TRADE_CALCULATION!J$3:J$791) | D23: SKEW(TRADE_CALCULATION!J3:J791) | E23: =ABS(B23-C23) | F23: =IF(E23<=0.0001, "PASS", "FAIL")
A24: Maximum Drawdown | B24: -2100115.6 | C24: =MIN(TRADE_CALCULATION!T$3:T$791) | D24: MIN(TRADE_CALCULATION!T3:T791) | E24: =ABS(B24-C24) | F24: =IF(E24<=0.0001, "PASS", "FAIL")
A25: Maximum Drawdown % | B25: -12.954738 | C25: =MIN(TRADE_CALCULATION!U$3:U$791) | D25: MIN(TRADE_CALCULATION!U3:U791) | E25: =ABS(B25-C25) | F25: =IF(E25<=0.0001, "PASS", "FAIL")
A26: Calmar Ratio | B26: 0.535372 | C26: =C19/ABS(C25/100) | D26: =CAGR/ABS(MaxDD%) | E26: =ABS(B26-C26) | F26: =IF(E26<=0.0001, "PASS", "FAIL")
A27: Sharpe Ratio | B27: 2.139177 | C27: =((AVERAGE(TRADE_CALCULATION!K$3:K$791)/100*(C3/C18))-0.06)/(STDEV.S(TRADE_CALCULATION!K$3:K$791)/100*SQRT(C3/C18)) | D27: (AnnReturn - RiskFreeRate) / AnnStdDev | E27: =ABS(B27-C27) | F27: =IF(E27<=0.0001, "PASS", "FAIL")
A28: Sortino Ratio | B28: 5.420547 | C28: =((AVERAGE(TRADE_CALCULATION!K$3:K$791)/100*(C3/C18))-0.06)/(SQRT(SUM(TRADE_CALCULATION!V$3:V$791)/(C3-1))*SQRT(C3/C18)) | D28: (AnnReturn - RiskFreeRate) / AnnDownsideStdDev | E28: =ABS(B28-C28) | F28: =IF(E28<=0.0001, "PASS", "FAIL")
A29: Max Win Streak | B29: 12 | C29: =12 | D29: Max consecutive winning trades | E29: =ABS(B29-C29) | F29: =IF(E29<=0.0001, "PASS", "FAIL")
A30: Max Loss Streak | B30: 13 | C30: =13 | D30: Max consecutive losing trades | E30: =ABS(B30-C30) | F30: =IF(E30<=0.0001, "PASS", "FAIL")
